Workbook

Sheet Lab 1
A1: Laboratorium 1 — Analiza danych eksperymentalnych
A3: Zadanie 1. Kwartet Anscombe’a
A4: Wariancja z próby: dzielnik n−1. Prosta regresji: y = beta0 + beta1 · x.
A6: Seria | B6: Śr. x | C6: Śr. y | D6: Var. x | E6: Var. y | F6: Pearson r | G6: beta0 | H6: beta1
A7: I | B7: =AVERAGE('Lab 1'!$B$113:$B$123) -> 9 | C7: =AVERAGE('Lab 1'!$C$113:$C$123) -> 7.5009091 | D7: =_xlfn.VAR.S('Lab 1'!$B$113:$B$123) -> 11 | E7: =_xlfn.VAR.S('Lab 1'!$C$113:$C$123) -> 4.1272691 | F7: =CORREL('Lab 1'!$B$113:$B$123,'Lab 1'!$C$113:$C$123) -> 0.81642052 | G7: =INTERCEPT('Lab 1'!$C$113:$C$123,'Lab 1'!$B$113:$B$123) -> 3.0000909 | H7: =SLOPE('Lab 1'!$C$113:$C$123,'Lab 1'!$B$113:$B$123) -> 0.50009091
A8: II | B8: =AVERAGE('Lab 1'!$D$113:$D$123) -> 9 | C8: =AVERAGE('Lab 1'!$E$113:$E$123) -> 7.5009091 | D8: =_xlfn.VAR.S('Lab 1'!$D$113:$D$123) -> 11 | E8: =_xlfn.VAR.S('Lab 1'!$E$113:$E$123) -> 4.1276291 | F8: =CORREL('Lab 1'!$D$113:$D$123,'Lab 1'!$E$113:$E$123) -> 0.81623651 | G8: =INTERCEPT('Lab 1'!$E$113:$E$123,'Lab 1'!$D$113:$D$123) -> 3.0009091 | H8: =SLOPE('Lab 1'!$E$113:$E$123,'Lab 1'!$D$113:$D$123) -> 0.5
A9: III | B9: =AVERAGE('Lab 1'!$F$113:$F$123) -> 9 | C9: =AVERAGE('Lab 1'!$G$113:$G$123) -> 7.5 | D9: =_xlfn.VAR.S('Lab 1'!$F$113:$F$123) -> 11 | E9: =_xlfn.VAR.S('Lab 1'!$G$113:$G$123) -> 4.12262 | F9: =CORREL('Lab 1'!$F$113:$F$123,'Lab 1'!$G$113:$G$123) -> 0.81628674 | G9: =INTERCEPT('Lab 1'!$G$113:$G$123,'Lab 1'!$F$113:$F$123) -> 3.0024545 | H9: =SLOPE('Lab 1'!$G$113:$G$123,'Lab 1'!$F$113:$F$123) -> 0.49972727
A10: IV | B10: =AVERAGE('Lab 1'!$H$113:$H$123) -> 9 | C10: =AVERAGE('Lab 1'!$I$113:$I$123) -> 7.5009091 | D10: =_xlfn.VAR.S('Lab 1'!$H$113:$H$123) -> 11 | E10: =_xlfn.VAR.S('Lab 1'!$I$113:$I$123) -> 4.1232491 | F10: =CORREL('Lab 1'!$H$113:$H$123,'Lab 1'!$I$113:$I$123) -> 0.81652144 | G10: =INTERCEPT('Lab 1'!$I$113:$I$123,'Lab 1'!$H$113:$H$123) -> 3.0017273 | H10: =SLOPE('Lab 1'!$I$113:$I$123,'Lab 1'!$H$113:$H$123) -> 0.49990909
A49: Zadanie 2. Zapis danych i usunięcie punktu odstającego
A51: Format | B51: Bajty | F51: Dane | G51: n | H51: beta0 | I51: beta1 | J51: R²
A52: CSV | B52: 555 | F52: Przed | G52: =COUNT('Lab 1'!$F$113:$F$123) -> 11 | H52: =INTERCEPT('Lab 1'!$G$113:$G$123,'Lab 1'!$F$113:$F$123) -> 3.0024545 | I52: =SLOPE('Lab 1'!$G$113:$G$123,'Lab 1'!$F$113:$F$123) -> 0.49972727 | J52: =RSQ('Lab 1'!$G$113:$G$123,'Lab 1'!$F$113:$F$123) -> 0.66632404
A53: JSON | B53: 1470 | F53: Po | G53: =COUNT('Lab 1'!$K$113:$K$122) -> 10 | H53: =INTERCEPT('Lab 1'!$L$113:$L$122,'Lab 1'!$K$113:$K$122) -> 4.0056494 | I53: =SLOPE('Lab 1'!$L$113:$L$122,'Lab 1'!$K$113:$K$122) -> 0.34538961 | J53: =RSQ('Lab 1'!$L$113:$L$122,'Lab 1'!$K$113:$K$122) -> 0.99999311
A54: XML | B54: 3033
A56: Reguła 1,5 × IQR dla y w serii III wskazała punkt (13; 12,74). Po filtracji pozostało 10 punktów.
A78: Zadanie 3. Porównanie serii 1, 9 i 10
A80: Seria | B80: Śr. x | C80: Śr. y | D80: Var. x | E80: Var. y | F80: Pearson r | G80: beta0 | H80: beta1
A81: seria1 | B81: =AVERAGE('Lab 1'!$B$129:$B$270) -> 54.263273 | C81: =AVERAGE('Lab 1'!$C$129:$C$270) -> 47.832253 | D81: =_xlfn.VAR.S('Lab 1'!$B$129:$B$270) -> 281.06999 | E81: =_xlfn.VAR.S('Lab 1'!$C$129:$C$270) -> 725.51596 | F81: =CORREL('Lab 1'!$B$129:$B$270,'Lab 1'!$C$129:$C$270) -> -0.064471853 | G81: =INTERCEPT('Lab 1'!$C$129:$C$270,'Lab 1'!$B$129:$B$270) -> 53.452978 | H81: =SLOPE('Lab 1'!$C$129:$C$270,'Lab 1'!$B$129:$B$270) -> -0.1035825
A82: seria9 | B82: =AVERAGE('Lab 1'!$D$129:$D$270) -> 54.26732 | C82: =AVERAGE('Lab 1'!$E$129:$E$270) -> 47.837717 | D82: =_xlfn.VAR.S('Lab 1'!$D$129:$D$270) -> 280.89802 | E82: =_xlfn.VAR.S('Lab 1'!$E$129:$E$270) -> 725.22684 | F82: =CORREL('Lab 1'!$D$129:$D$270,'Lab 1'!$E$129:$E$270) -> -0.068343356 | G82: =INTERCEPT('Lab 1'!$E$129:$E$270,'Lab 1'!$D$129:$D$270) -> 53.797045 | H82: =SLOPE('Lab 1'!$E$129:$E$270,'Lab 1'!$D$129:$D$270) -> -0.1098143
A83: seria10 | B83: =AVERAGE('Lab 1'!$F$129:$F$270) -> 54.26873 | C83: =AVERAGE('Lab 1'!$G$129:$G$270) -> 47.830823 | D83: =_xlfn.VAR.S('Lab 1'!$F$129:$F$270) -> 281.20739 | E83: =_xlfn.VAR.S('Lab 1'!$G$129:$G$270) -> 725.53337 | F83: =CORREL('Lab 1'!$F$129:$F$270,'Lab 1'!$G$129:$G$270) -> -0.068586394 | G83: =INTERCEPT('Lab 1'!$G$129:$G$270,'Lab 1'!$F$129:$F$270) -> 53.809471 | H83: =SLOPE('Lab 1'!$G$129:$G$270,'Lab 1'!$F$129:$F$270) -> -0.11016745
A110: Dane źródłowe użyte w tabelach i wykresach
A112: Nr | B112: x I | C112: y I | D112: x II | E112: y II | F112: x III | G112: y III | H112: x IV | I112: y IV | K112: x III po | L112: y III po
A113: 1 | B113: 10 | C113: 8.04 | D113: 10 | E113: 9.14 | F113: 10 | G113: 7.46 | H113: 8 | I113: 6.58 | K113: =F113 -> 10 | L113: =G113 -> 7.46
A114: 2 | B114: 8 | C114: 6.95 | D114: 8 | E114: 8.14 | F114: 8 | G114: 6.77 | H114: 8 | I114: 5.76 | K114: =F114 -> 8 | L114: =G114 -> 6.77
A115: 3 | B115: 13 | C115: 7.58 | D115: 13 | E115: 8.74 | F115: 13 | G115: 12.74 | H115: 8 | I115: 7.71 | K115: =F116 -> 9 | L115: =G116 -> 7.11
A116: 4 | B116: 9 | C116: 8.81 | D116: 9 | E116: 8.77 | F116: 9 | G116: 7.11 | H116: 8 | I116: 8.84 | K116: =F117 -> 11 | L116: =G117 -> 7.81
A117: 5 | B117: 11 | C117: 8.33 | D117: 11 | E117: 9.26 | F117: 11 | G117: 7.81 | H117: 8 | I117: 8.47 | K117: =F118 -> 14 | L117: =G118 -> 8.84
A118: 6 | B118: 14 | C118: 9.96 | D118: 14 | E118: 8.1 | F118: 14 | G118: 8.84 | H118: 8 | I118: 7.04 | K118: =F119 -> 6 | L118: =G119 -> 6.08
A119: 7 | B119: 6 | C119: 7.24 | D119: 6 | E119: 6.13 | F119: 6 | G119: 6.08 | H119: 8 | I119: 5.25 | K119: =F120 -> 4 | L119: =G120 -> 5.39
A120: 8 | B120: 4 | C120: 4.26 | D120: 4 | E120: 3.1 | F120: 4 | G120: 5.39 | H120: 19 | I120: 12.5 | K120: =F121 -> 12 | L120: =G121 -> 8.15
A121: 9 | B121: 12 | C121: 10.84 | D121: 12 | E121: 9.13 | F121: 12 | G121: 8.15 | H121: 8 | I121: 5.56 | K121: =F122 -> 7 | L121: =G122 -> 6.42
A122: 10 | B122: 7 | C122: 4.82 | D122: 7 | E122: 7.26 | F122: 7 | G122: 6.42 | H122: 8 | I122: 7.91 | K122: =F123 -> 5 | L122: =G123 -> 5.73
A123: 11 | B123: 5 | C123: 5.68 | D123: 5 | E123: 4.74 | F123: 5 | G123: 5.73 | H123: 8 | I123: 6.89
A128: Nr | B128: x seria1 | C128: y seria1 | D128: x seria9 | E128: y seria9 | F128: x seria10 | G128: y seria10
A129: 1 | B129: 55.3846 | C129: 97.1795 | D129: 55.99303 | E129: 79.277264 | F129: 51.203891 | G129: 83.339777 | I129: Prosta: Seria I
A130: 2 | B130: 51.5385 | C130: 96.0256 | D130: 50.032254 | E130: 79.013071 | F130: 58.97447 | G130: 85.499818 | I130: 3 | J130: =G7+H7*I130 -> 4.5003636
A131: 3 | B131: 46.1538 | C131: 94.4872 | D131: 51.288459 | E131: 82.43594 | F131: 51.872073 | G131: 85.829738 | I131: 20 | J131: =G7+H7*I131 -> 13.001909
A132: 4 | B132: 42.8205 | C132: 91.4103 | D132: 51.170537 | E132: 79.165294 | F132: 48.179931 | G132: 85.045117
A133: 5 | B133: 40.7692 | C133: 88.3333 | D133: 44.377915 | E133: 78.164628 | F133: 41.6832 | G133: 84.017941 | I133: Prosta: Seria II
A134: 6 | B134: 38.7179 | C134: 84.8718 | D134: 45.01027 | E134: 77.880863 | F134: 37.890416 | G134: 82.567493 | I134: 3 | J134: =G8+H8*I134 -> 4.5009091
A135: 7 | B135: 35.641 | C135: 79.8718 | D135: 48.559817 | E135: 78.788371 | F135: 39.548974 | G135: 80.812602 | I135: 20 | J135: =G8+H8*I135 -> 13.000909
...
